Workbook

Sheet Data
A1: Timestamp | B1: What is your gender? | C1: Which year are you born in? | D1: Approximate monthly personal income in forints? | E1: Employment status? | F1: What factors influence your decision to buy eco-friendly products? | G1: Protecting the environment should be prioritized. | H1: I consider it my personal responsibility to reduce waste. | I1: Companies hold the responsibility to minimize the environmental impact of their products. | J1: I prefer to purchase products that are environmentally friendly, even if they come at a higher price. | K1: I prefer products with eco-friendly packaging over conventional packaging. | L1: I worry about how today’s packaging waste will affect future generations. | M1: I actively seek information regarding the sustainability of the products I purchase. | N1: I trust in a company's claims regarding the environmental benefits of its packaging | O1: Brands often exaggerate the environmental benefits of their products. | P1: I often find it challenging to determine which brands truly practice sustainability | Q1: I would be willing to change my purchasing habits based on new information about a product's environmental impact. | R1: Imagine your usual bread costs 400 forints. If that same bread cost 460 forints, would you be willing to pay an additional 10% for eco-friendly packaging?" | S1: I would pick a more expensive product with eco-friendly packaging instead of a cheaper one with regular packaging. | T1: I think companies should use sustainable packaging, even if their products cost more. | U1: I am cautious about trusting sustainability claims made by brands | V1: I worry that some companies pretend to be eco-friendly just to attract customers. | W1: I think there should be stricter rules to stop companies from making false environmental claims. | X1: I get frustrated when brands use “green” words without proving their products are truly sustainable. | Y1: Score | Z1: Generation
A2: 45986.557 | B2: Female | C2: 2003 | D2: 250,000 - 400,000 | E2: Part time employment | F2: Personal values | G2: 5 | H2: 5 | I2: 5 | J2: 4 | K2: 4 | L2: 5 | M2: 5 | N2: 5 | O2: 4 | P2: 4 | Q2: 5 | R2: 5 | S2: 5 | T2: 5 | U2: 5 | V2: 5 | W2: 5 | X2: 5 | Z2: Gen Z (1997 - 2012)
A3: 45986.558 | B3: Male | C3: 1997 | D3: under 250,000 | E3: Full time employment | F3: To improved performance in productions | G3: 5 | H3: 5 | I3: 1 | J3: 3 | K3: 1 | L3: 5 | M3: 5 | N3: 5 | O3: 5 | P3: 5 | Q3: 5 | R3: 3 | S3: 3 | T3: 5 | U3: 5 | V3: 5 | W3: 5 | X3: 5 | Z3: Gen Z (1997 - 2012)
A4: 45986.559 | B4: Female | C4: 1997 | D4: 250,000 - 400,000 | E4: Part time employment | F4: To be mindful of my environment. | G4: 5 | H4: 5 | I4: 4 | J4: 4 | K4: 4 | L4: 5 | M4: 4 | N4: 4 | O4: 5 | P4: 5 | Q4: 4 | R4: 4 | S4: 4 | T4: 2 | U4: 4 | V4: 4 | W4: 4 | X4: 4 | Z4: Gen Z (1997 - 2012)
A5: 45986.56 | B5: Female | C5: 2004 | D5: under 250,000 | E5: Unemployed | F5: Price | G5: 3 | H5: 3 | I5: 3 | J5: 4 | K5: 3 | L5: 4 | M5: 4 | N5: 4 | O5: 4 | P5: 5 | Q5: 4 | R5: 2 | S5: 3 | T5: 4 | U5: 3 | V5: 4 | W5: 4 | X5: 2 | Z5: Gen Z (1997 - 2012)
A6: 45986.568 | B6: Male | C6: 1997 | D6: 250,000 - 400,000 | E6: Full time employment | F6: Human health factors | G6: 1 | H6: 1 | I6: 1 | J6: 1 | K6: 1 | L6: 1 | M6: 1 | N6: 1 | O6: 3 | P6: 1 | Q6: 1 | R6: 1 | S6: 1 | T6: 1 | U6: 1 | V6: 1 | W6: 1 | X6: 1 | Z6: Gen Z (1997 - 2012)
A7: 45986.57 | B7: Male | C7: 1997 | D7: under 250,000 | E7: Part time employment | F7: Prices | G7: 4 | H7: 5 | I7: 4 | J7: 5 | K7: 4 | L7: 5 | M7: 4 | N7: 2 | O7: 2 | P7: 3 | Q7: 2 | R7: 4 | S7: 3 | T7: 2 | U7: 3 | V7: 3 | W7: 1 | X7: 3 | Z7: Gen Z (1997 - 2012)
A8: 45986.576 | B8: Male | C8: 2007 | D8: 600,000 and above | E8: Unemployed | F8: The emerging threat of enviroment degradation and climate change | G8: 4 | H8: 4 | I8: 5 | J8: 1 | K8: 2 | L8: 4 | M8: 4 | N8: 1 | O8: 5 | P8: 4 | Q8: 4 | R8: 2 | S8: 1 | T8: 5 | U8: 5 | V8: 5 | W8: 5 | X8: 5 | Z8: Gen Z (1997 - 2012)
A9: 45986.58 | B9: Male | C9: 1997 | D9: 250,000 - 400,000 | E9: Unemployed | F9: If the price is the same I'll get the eco friendly | G9: 4 | H9: 2 | I9: 5 | J9: 2 | K9: 5 | L9: 4 | M9: 1 | N9: 4 | O9: 5 | P9: 5 | Q9: 4 | R9: 2 | S9: 2 | T9: 4 | U9: 5 | V9: 5 | W9: 5 | X9: 5 | Z9: Gen Z (1997 - 2012)
A10: 45986.586 | B10: Male | C10: 1969 | D10: under 250,000 | E10: Full time employment | F10: It saves us and our health | G10: 5 | H10: 5 | I10: 4 | J10: 5 | K10: 5 | L10: 4 | M10: 4 | N10: 4 | O10: 4 | P10: 4 | Q10: 4 | R10: 4 | S10: 4 | T10: 4 | U10: 4 | V10: 4 | W10: 5 | X10: 5 | Z10: Gen X (1965 - 1980)
A11: 45986.597 | B11: Female | C11: 1997 | D11: under 250,000 | E11: Unemployed | F11: Prices | G11: 5 | H11: 5 | I11: 4 | J11: 4 | K11: 5 | L11: 5 | M11: 4 | N11: 2 | O11: 5 | P11: 5 | Q11: 5 | R11: 5 | S11: 4 | T11: 5 | U11: 5 | V11: 5 | W11: 5 | X11: 5 | Z11: Gen Z (1997 - 2012)
A12: 45986.683 | B12: Female | C12: 2002 | D12: under 250,000 | E12: Part time employment | F12: Price and budget , accessibility and usage. | G12: 5 | H12: 4 | I12: 3 | J12: 2 | K12: 2 | L12: 4 | M12: 2 | N12: 3 | O12: 5 | P12: 5 | Q12: 4 | R12: 4 | S12: 2 | T12: 3 | U12: 5 | V12: 5 | W12: 5 | X12: 5 | Z12: Gen Z (1997 - 2012)
A13: 45986.691 | B13: Male | C13: 2000 | D13: 250,000 - 400,000 | E13: Unemployed | F13: I just buy what I want | G13: 1 | H13: 3 | I13: 2 | J13: 3 | K13: 4 | L13: 4 | M13: 3 | N13: 4 | O13: 5 | P13: 2 | Q13: 4 | R13: 3 | S13: 2 | T13: 2 | U13: 4 | V13: 4 | W13: 4 | X13: 4 | Z13: Gen Z (1997 - 2012)
... A32: 45990.766 | B32: Female | C32: 1980 | D32: 400,000 - 600,000 | E32: Full time employment | F32: Social influence | G32: 5 | H32: 5 | I32: 5 | J32: 4 | K32: 5 | L32: 5 | M32: 4 | N32: 2 | O32: 5 | P32: 4 | Q32: 4 | R32: 4 | S32: 2 | T32: 4 | U32: 2 | V32: 5 | W32: 5 | X32: 5 | Z32: Gen X (1965 - 1980)
A33: 45990.924 | B33: Male | C33: 1999 | D33: 250,000 - 400,000 | E33: Part time employment | F33: Global warming, climatic changes, product quality and price. | G33: 4 | H33: 4 | I33: 4 | J33: 4 | K33: 4 | L33: 4 | M33: 4 | N33: 2 | O33: 5 | P33: 3 | Q33: 3 | R33: 4 | S33: 3 | T33: 4 | U33: 3 | V33: 3 | W33: 5 | X33: 5 | Y33: 0 | Z33: Gen Z (1997 - 2012)
A34: 45991.574 | B34: Male | C34: 2001 | D34: 250,000 - 400,000 | E34: Part time employment | F34: Price, quality and earth ecosystem. | G34: 5 | H34: 4 | I34: 4 | J34: 3 | K34: 4 | L34: 4 | M34: 2 | N34: 5 | O34: 2 | P34: 3 | Q34: 2 | R34: 4 | S34: 2 | T34: 2 | U34: 2 | V34: 4 | W34: 4 | X34: 4 | Y34: 0 | Z34: Gen Z (1997 - 2012)
A35: 45991.58 | B35: Male | C35: 2005 | D35: under 250,000 | E35: Unemployed | F35: availability and convenience of the products | G35: 5 | H35: 5 | I35: 4 | J35: 4 | K35: 4 | L35: 4 | M35: 4 | N35: 4 | O35: 5 | P35: 2 | Q35: 2 | R35: 4 | S35: 4 | T35: 4 | U35: 4 | V35: 3 | W35: 5 | X35: 5 | Y35: 0 | Z35: Gen Z (1997 - 2012)
A36: 45991.581 | B36: Female | C36: 2002 | D36: under 250,000 | E36: Unemployed | F36: Concern for environment and health | G36: 5 | H36: 4 | I36: 4 | J36: 4 | K36: 5 | L36: 5 | M36: 4 | N36: 4 | O36: 3 | P36: 2 | Q36: 2 | R36: 4 | S36: 3 | T36: 2 | U36: 4 | V36: 3 | W36: 5 | X36: 5 | Y36: 0 | Z36: Gen Z (1997 - 2012)
A37: 45991.584 | B37: Male | C37: 1999 | D37: 250,000 - 400,000 | E37: Part time employment | F37: Glad to contribute for green initiative programs or products keeping earth's safety into consideration as there are a lot of pollution is causing global warming.! | G37: 5 | H37: 5 | I37: 4 | J37: 3 | K37: 5 | L37: 5 | M37: 4 | N37: 4 | O37: 2 | P37: 2 | Q37: 2 | R37: 4 | S37: 2 | T37: 2 | U37: 4 | V37: 2 | W37: 5 | X37: 5 | Y37: 0 | Z37: Gen Z (1997 - 2012)
A38: 45991.587 | B38: Female | C38: 1998 | D38: 250,000 - 400,000 | E38: Part time employment | F38: Positive attitude towards eco friendly products | G38: 4 | H38: 4 | I38: 4 | J38: 4 | K38: 5 | L38: 5 | M38: 4 | N38: 4 | O38: 3 | P38: 2 | Q38: 4 | R38: 4 | S38: 2 | T38: 2 | U38: 4 | V38: 2 | W38: 5 | X38: 5 | Y38: 0 | Z38: Gen Z (1997 - 2012)
A39: 45991.591 | B39: Male | C39: 2003 | D39: under 250,000 | E39: Part time employment | F39: Positive past experience with packaging green products | G39: 5 | H39: 4 | I39: 4 | J39: 3 | K39: 4 | L39: 4 | M39: 4 | N39: 3 | O39: 3 | P39: 2 | Q39: 2 | R39: 2 | S39: 2 | T39: 3 | U39: 4 | V39: 3 | W39: 5 | X39: 5 | Y39: 0 | Z39: Gen Z (1997 - 2012)

Sheet GenX
A1: Timestamp | B1: What is your gender? | C1: Which year are you born in? | D1: Approximate monthly personal income in forints? | E1: Employment status? | F1: What factors influence your decision to buy eco-friendly products? | G1: Protecting the environment should be prioritized. | H1: I consider it my personal responsibility to reduce waste. | I1: Companies hold the responsibility to minimize the environmental impact of their products. | J1: I prefer to purchase products that are environmentally friendly, even if they come at a higher price. | K1: I prefer products with eco-friendly packaging over conventional packaging. | L1: I worry about how today’s packaging waste will affect future generations. | M1: I actively seek information regarding the sustainability of the products I purchase. | N1: I trust in a company's claims regarding the environmental benefits of its packaging | O1: Brands often exaggerate the environmental benefits of their products. | P1: I often find it challenging to determine which brands truly practice sustainability | Q1: I would be willing to change my purchasing habits based on new information about a product's environmental impact. | R1: Imagine your usual bread costs 400 forints. If that same bread cost 460 forints, would you be willing to pay an additional 10% for eco-friendly packaging?" | S1: I would pick a more expensive product with eco-friendly packaging instead of a cheaper one with regular packaging. | T1: I think companies should use sustainable packaging, even if their products cost more. | U1: I am cautious about trusting sustainability claims made by brands | V1: I worry that some companies pretend to be eco-friendly just to attract customers. | W1: I think there should be stricter rules to stop companies from making false environmental claims. | X1: I get frustrated when brands use “green” words without proving their products are truly sustainable. | Y1: Score | Z1: Generation
A2: 45986.586 | B2: Male | C2: 1969 | D2: under 250,000 | E2: Full time employment | F2: It saves us and our health | G2: 5 | H2: 5 | I2: 4 | J2: 5 | K2: 5 | L2: 4 | M2: 4 | N2: 4 | O2: 4 | P2: 4 | Q2: 4 | R2: 4 | S2: 4 | T2: 4 | U2: 4 | V2: 4 | W2: 5 | X2: 5 | Z2: Gen X (1965 - 1980)
A3: 45988.763 | B3: Female | C3: 1979 | D3: 600,000 and above | E3: Retired | F3: Price | G3: 5 | H3: 5 | I3: 5 | J3: 4 | K3: 5 | L3: 5 | M3: 4 | N3: 3 | O3: 3 | P3: 5 | Q3: 4 | R3: 3 | S3: 3 | T3: 4 | U3: 5 | V3: 5 | W3: 5 | X3: 3 | Z3: Gen X (1965 - 1980)
A4: 45988.783 | B4: Male | C4: 1976 | D4: under 250,000 | E4: Full time employment | F4: Many factors influenece | G4: 4 | H4: 3 | I4: 4 | J4: 5 | K4: 3 | L4: 4 | M4: 2 | N4: 4 | O4: 5 | P4: 2 | Q4: 3 | R4: 3 | S4: 4 | T4: 4 | U4: 4 | V4: 4 | W4: 4 | X4: 5 | Z4: Gen X (1965 - 1980)
A5: 45988.788 | B5: Female | C5: 1975 | D5: 400,000 - 600,000 | E5: Full time employment | F5: For healthy environment and health conscious | G5: 5 | H5: 5 | I5: 5 | J5: 5 | K5: 5 | L5: 5 | M5: 4 | N5: 1 | O5: 5 | P5: 5 | Q5: 1 | R5: 5 | S5: 5 | T5: 5 | U5: 1 | V5: 5 | W5: 5 | X5: 5 | Z5: Gen X (1965 - 1980)
A6: 45988.791 | B6: Female | C6: 1980 | D6: 600,000 and above | E6: Full time employment | F6: Earth's atmosphere is getting polluted. | G6: 5 | H6: 5 | I6: 5 | J6: 4 | K6: 5 | L6: 5 | M6: 3 | N6: 1 | O6: 5 | P6: 5 | Q6: 1 | R6: 3 | S6: 4 | T6: 4 | U6: 1 | V6: 5 | W6: 5 | X6: 5 | Z6: Gen X (1965 - 1980)
A7: 45988.797 | B7: Male | C7: 1980 | D7: 600,000 and above | E7: Full time employment | F7: To reduce carbon footprint and pollution. Go green, save earth. | G7: 5 | H7: 4 | I7: 5 | J7: 4 | K7: 5 | L7: 5 | M7: 3 | N7: 1 | O7: 5 | P7: 4 | Q7: 2 | R7: 4 | S7: 4 | T7: 3 | U7: 2 | V7: 5 | W7: 5 | X7: 4 | Z7: Gen X (1965 - 1980)
A8: 45990.737 | B8: Female | C8: 1965 | D8: 600,000 and above | E8: Retired | F8: Money, product, quality of product, location | G8: 4 | H8: 5 | I8: 3 | J8: 5 | K8: 3 | L8: 4 | M8: 2 | N8: 5 | O8: 4 | P8: 2 | Q8: 5 | R8: 3 | S8: 4 | T8: 3 | U8: 5 | V8: 3 | W8: 4 | X8: 4 | Z8: Gen X (1965 - 1980)
A9: 45990.75 | B9: Female | C9: 1973 | D9: 600,000 and above | E9: Full time employment | F9: For earth's safety, to reduce pollution caused by using plastics and other conventional methods. | G9: 5 | H9: 5 | I9: 5 | J9: 4 | K9: 4 | L9: 5 | M9: 3 | N9: 1 | O9: 5 | P9: 4 | Q9: 5 | R9: 5 | S9: 2 | T9: 2 | U9: 3 | V9: 4 | W9: 4 | X9: 5 | Z9: Gen X (1965 - 1980)
A10: 45990.754 | B10: Female | C10: 1971 | D10: 600,000 and above | E10: Full time employment | F10: Price, product quality, packaging. | G10: 4 | H10: 5 | I10: 4 | J10: 2 | K10: 4 | L10: 4 | M10: 4 | N10: 2 | O10: 4 | P10: 4 | Q10: 2 | R10: 2 | S10: 2 | T10: 2 | U10: 2 | V10: 5 | W10: 5 | X10: 5 | Z10: Gen X (1965 - 1980)
A11: 45990.757 | B11: Female | C11: 1979 | D11: 250,000 - 400,000 | E11: Retired | F11: No Ans | G11: 4 | H11: 3 | I11: 3 | J11: 4 | K11: 4 | L11: 3 | M11: 2 | N11: 4 | O11: 3 | P11: 5 | Q11: 3 | R11: 4 | S11: 5 | T11: 5 | U11: 3 | V11: 3 | W11: 5 | X11: 2 | Z11: Gen X (1965 - 1980)
A12: 45990.766 | B12: Female | C12: 1980 | D12: 400,000 - 600,000 | E12: Full time employment | F12: Social influence | G12: 5 | H12: 5 | I12: 5 | J12: 4 | K12: 5 | L12: 5 | M12: 4 | N12: 2 | O12: 5 | P12: 4 | Q12: 4 | R12: 4 | S12: 2 | T12: 4 | U12: 2 | V12: 5 | W12: 5 | X12: 5 | Z12: Gen X (1965 - 1980)

Sheet GenZ
A1: Timestamp | B1: What is your gender? | C1: Which year are you born in? | D1: Approximate monthly personal income in forints? | E1: Employment status? | F1: What factors influence your decision to buy eco-friendly products? | G1: Protecting the environment should be prioritized. | H1: I consider it my personal responsibility to reduce waste. | I1: Companies hold the responsibility to minimize the environmental impact of their products. | J1: I prefer to purchase products that are environmentally friendly, even if they come at a higher price. | K1: I prefer products with eco-friendly packaging over conventional packaging. | L1: I worry about how today’s packaging waste will affect future generations. | M1: I actively seek information regarding the sustainability of the products I purchase. | N1: I trust in a company's claims regarding the environmental benefits of its packaging | O1: Brands often exaggerate the environmental benefits of their products. | P1: I often find it challenging to determine which brands truly practice sustainability | Q1: I would be willing to change my purchasing habits based on new information about a product's environmental impact. | R1: Imagine your usual bread costs 400 forints. If that same bread cost 460 forints, would you be willing to pay an additional 10% for eco-friendly packaging?" | S1: I would pick a more expensive product with eco-friendly packaging instead of a cheaper one with regular packaging. | T1: I think companies should use sustainable packaging, even if their products cost more. | U1: I am cautious about trusting sustainability claims made by brands | V1: I worry that some companies pretend to be eco-friendly just to attract customers. | W1: I think there should be stricter rules to stop companies from making false environmental claims. | X1: I get frustrated when brands use “green” words without proving their products are truly sustainable. | Y1: Score | Z1: Generation
A2: 45986.557 | B2: Female | C2: 2003 | D2: 250,000 - 400,000 | E2: Part time employment | F2: Personal values | G2: 5 | H2: 5 | I2: 5 | J2: 4 | K2: 4 | L2: 5 | M2: 5 | N2: 5 | O2: 4 | P2: 4 | Q2: 5 | R2: 5 | S2: 5 | T2: 5 | U2: 5 | V2: 5 | W2: 5 | X2: 5 | Z2: Gen Z (1997 - 2012)
A3: 45986.558 | B3: Male | C3: 1997 | D3: under 250,000 | E3: Full time employment | F3: To improved performance in productions | G3: 5 | H3: 5 | I3: 1 | J3: 3 | K3: 1 | L3: 5 | M3: 5 | N3: 5 | O3: 5 | P3: 5 | Q3: 5 | R3: 3 | S3: 3 | T3: 5 | U3: 5 | V3: 5 | W3: 5 | X3: 5 | Z3: Gen Z (1997 - 2012)
A4: 45986.559 | B4: Female | C4: 1997 | D4: 250,000 - 400,000 | E4: Part time employment | F4: To be mindful of my environment. | G4: 5 | H4: 5 | I4: 4 | J4: 4 | K4: 4 | L4: 5 | M4: 4 | N4: 4 | O4: 5 | P4: 5 | Q4: 4 | R4: 4 | S4: 4 | T4: 2 | U4: 4 | V4: 4 | W4: 4 | X4: 4 | Z4: Gen Z (1997 - 2012)
A5: 45986.56 | B5: Female | C5: 2004 | D5: under 250,000 | E5: Unemployed | F5: Price | G5: 3 | H5: 3 | I5: 3 | J5: 4 | K5: 3 | L5: 4 | M5: 4 | N5: 4 | O5: 4 | P5: 5 | Q5: 4 | R5: 2 | S5: 3 | T5: 4 | U5: 3 | V5: 4 | W5: 4 | X5: 2 | Z5: Gen Z (1997 - 2012)
A6: 45986.568 | B6: Male | C6: 1997 | D6: 250,000 - 400,000 | E6: Full time employment | F6: Human health factors | G6: 1 | H6: 1 | I6: 1 | J6: 1 | K6: 1 | L6: 1 | M6: 1 | N6: 1 | O6: 3 | P6: 1 | Q6: 1 | R6: 1 | S6: 1 | T6: 1 | U6: 1 | V6: 1 | W6: 1 | X6: 1 | Z6: Gen Z (1997 - 2012)
A7: 45986.57 | B7: Male | C7: 1997 | D7: under 250,000 | E7: Part time employment | F7: Prices | G7: 4 | H7: 5 | I7: 4 | J7: 5 | K7: 4 | L7: 5 | M7: 4 | N7: 2 | O7: 2 | P7: 3 | Q7: 2 | R7: 4 | S7: 3 | T7: 2 | U7: 3 | V7: 3 | W7: 1 | X7: 3 | Z7: Gen Z (1997 - 2012)
A8: 45986.576 | B8: Male | C8: 2007 | D8: 600,000 and above | E8: Unemployed | F8: The emerging threat of enviroment degradation and climate change | G8: 4 | H8: 4 | I8: 5 | J8: 1 | K8: 2 | L8: 4 | M8: 4 | N8: 1 | O8: 5 | P8: 4 | Q8: 4 | R8: 2 | S8: 1 | T8: 5 | U8: 5 | V8: 5 | W8: 5 | X8: 5 | Z8: Gen Z (1997 - 2012)
A9: 45986.58 | B9: Male | C9: 1997 | D9: 250,000 - 400,000 | E9: Unemployed | F9: If the price is the same I'll get the eco friendly | G9: 4 | H9: 2 | I9: 5 | J9: 2 | K9: 5 | L9: 4 | M9: 1 | N9: 4 | O9: 5 | P9: 5 | Q9: 4 | R9: 2 | S9: 2 | T9: 4 | U9: 5 | V9: 5 | W9: 5 | X9: 5 | Z9: Gen Z (1997 - 2012)
A10: 45986.597 | B10: Female | C10: 1997 | D10: under 250,000 | E10: Unemployed | F10: Prices | G10: 5 | H10: 5 | I10: 4 | J10: 4 | K10: 5 | L10: 5 | M10: 4 | N10: 2 | O10: 5 | P10: 5 | Q10: 5 | R10: 5 | S10: 4 | T10: 5 | U10: 5 | V10: 5 | W10: 5 | X10: 5 | Z10: Gen Z (1997 - 2012)
A11: 45986.683 | B11: Female | C11: 2002 | D11: under 250,000 | E11: Part time employment | F11: Price and budget , accessibility and usage. | G11: 5 | H11: 4 | I11: 3 | J11: 2 | K11: 2 | L11: 4 | M11: 2 | N11: 3 | O11: 5 | P11: 5 | Q11: 4 | R11: 4 | S11: 2 | T11: 3 | U11: 5 | V11: 5 | W11: 5 | X11: 5 | Z11: Gen Z (1997 - 2012)
A12: 45986.691 | B12: Male | C12: 2000 | D12: 250,000 - 400,000 | E12: Unemployed | F12: I just buy what I want | G12: 1 | H12: 3 | I12: 2 | J12: 3 | K12: 4 | L12: 4 | M12: 3 | N12: 4 | O12: 5 | P12: 2 | Q12: 4 | R12: 3 | S12: 2 | T12: 2 | U12: 4 | V12: 4 | W12: 4 | X12: 4 | Z12: Gen Z (1997 - 2012)
A13: 45986.782 | B13: Female | C13: 2003 | D13: under 250,000 | E13: Part time employment | F13: Marine life mostly | G13: 4 | H13: 1 | I13: 5 | J13: 4 | K13: 4 | L13: 5 | M13: 3 | N13: 4 | O13: 5 | P13: 4 | Q13: 4 | R13: 5 | S13: 4 | T13: 3 | U13: 4 | V13: 5 | W13: 5 | X13: 5 | Z13: Gen Z (1997 - 2012)
... A21: 45989.155 | B21: Male | C21: 1999 | D21: under 250,000 | E21: Full time employment | F21: Growing pollution and improper waste management | G21: 5 | H21: 5 | I21: 5 | J21: 5 | K21: 5 | L21: 5 | M21: 5 | N21: 5 | O21: 5 | P21: 5 | Q21: 5 | R21: 5 | S21: 5 | T21: 5 | U21: 5 | V21: 5 | W21: 5 | X21: 5 | Z21: Gen Z (1997 - 2012)
A22: 45990.924 | B22: Male | C22: 1999 | D22: 250,000 - 400,000 | E22: Part time employment | F22: Global warming, climatic changes, product quality and price. | G22: 4 | H22: 4 | I22: 4 | J22: 4 | K22: 4 | L22: 4 | M22: 4 | N22: 2 | O22: 5 | P22: 3 | Q22: 3 | R22: 4 | S22: 3 | T22: 4 | U22: 3 | V22: 3 | W22: 5 | X22: 5 | Y22: 0 | Z22: Gen Z (1997 - 2012)
A23: 45991.574 | B23: Male | C23: 2001 | D23: 250,000 - 400,000 | E23: Part time employment | F23: Price, quality and earth ecosystem. | G23: 5 | H23: 4 | I23: 4 | J23: 3 | K23: 4 | L23: 4 | M23: 2 | N23: 5 | O23: 2 | P23: 3 | Q23: 2 | R23: 4 | S23: 2 | T23: 2 | U23: 2 | V23: 4 | W23: 4 | X23: 4 | Y23: 0 | Z23: Gen Z (1997 - 2012)
A24: 45991.58 | B24: Male | C24: 2005 | D24: under 250,000 | E24: Unemployed | F24: availability and convenience of the products | G24: 5 | H24: 5 | I24: 4 | J24: 4 | K24: 4 | L24: 4 | M24: 4 | N24: 4 | O24: 5 | P24: 2 | Q24: 2 | R24: 4 | S24: 4 | T24: 4 | U24: 4 | V24: 3 | W24: 5 | X24: 5 | Y24: 0 | Z24: Gen Z (1997 - 2012)
A25: 45991.581 | B25: Female | C25: 2002 | D25: under 250,000 | E25: Unemployed | F25: Concern for environment and health | G25: 5 | H25: 4 | I25: 4 | J25: 4 | K25: 5 | L25: 5 | M25: 4 | N25: 4 | O25: 3 | P25: 2 | Q25: 2 | R25: 4 | S25: 3 | T25: 2 | U25: 4 | V25: 3 | W25: 5 | X25: 5 | Y25: 0 | Z25: Gen Z (1997 - 2012)
A26: 45991.584 | B26: Male | C26: 1999 | D26: 250,000 - 400,000 | E26: Part time employment | F26: Glad to contribute for green initiative programs or products keeping earth's safety into consideration as there are a lot of pollution is causing global warming.! | G26: 5 | H26: 5 | I26: 4 | J26: 3 | K26: 5 | L26: 5 | M26: 4 | N26: 4 | O26: 2 | P26: 2 | Q26: 2 | R26: 4 | S26: 2 | T26: 2 | U26: 4 | V26: 2 | W26: 5 | X26: 5 | Y26: 0 | Z26: Gen Z (1997 - 2012)
A27: 45991.587 | B27: Female | C27: 1998 | D27: 250,000 - 400,000 | E27: Part time employment | F27: Positive attitude towards eco friendly products | G27: 4 | H27: 4 | I27: 4 | J27: 4 | K27: 5 | L27: 5 | M27: 4 | N27: 4 | O27: 3 | P27: 2 | Q27: 4 | R27: 4 | S27: 2 | T27: 2 | U27: 4 | V27: 2 | W27: 5 | X27: 5 | Y27: 0 | Z27: Gen Z (1997 - 2012)
A28: 45991.591 | B28: Male | C28: 2003 | D28: under 250,000 | E28: Part time employment | F28: Positive past experience with packaging green products | G28: 5 | H28: 4 | I28: 4 | J28: 3 | K28: 4 | L28: 4 | M28: 4 | N28: 3 | O28: 3 | P28: 2 | Q28: 2 | R28: 2 | S28: 2 | T28: 3 | U28: 4 | V28: 3 | W28: 5 | X28: 5 | Y28: 0 | Z28: Gen Z (1997 - 2012)

Sheet X&Z_Agrees_Avg
B1: Protecting the environment should be prioritized. | C1: I consider it my personal responsibility to reduce waste. | D1: Companies hold the responsibility to minimize the environmental impact of their products. | E1: I prefer to purchase products that are environmentally friendly, even if they come at a higher price. | F1: I prefer products with eco-friendly packaging over conventional packaging. | G1: I worry about how today’s packaging waste will affect future generations. | H1: I actively seek information regarding the sustainability of the products I purchase. | I1: I trust in a company's claims regarding the environmental benefits of its packaging | J1: Brands often exaggerate the environmental benefits of their products. | K1: I often find it challenging to determine which brands truly practice sustainability | L1: I would be willing to change my purchasing habits based on new information about a product's environmental impact. | M1: Imagine your usual bread costs 400 forints. If that same bread cost 460 forints, would you be willing to pay an additional 10% for eco-friendly packaging?" | N1: I would pick a more expensive product with eco-friendly packaging instead of a cheaper one with regular packaging. | O1: I think companies should use sustainable packaging, even if their products cost more. | P1: I am cautious about trusting sustainability claims made by brands | Q1: I worry that some companies pretend to be eco-friendly just to attract customers. | R1: I think there should be stricter rules to stop companies from making false environmental claims. | S1: I get frustrated when brands use “green” words without proving their products are truly sustainable. | T1: Generation
B2: 5 | C2: 5 | D2: 5 | E2: 4 | F2: 4 | G2: 5 | H2: 5 | I2: 5 | J2: 4 | K2: 4 | L2: 5 | M2: 5 | N2: 5 | O2: 5 | P2: 5 | Q2: 5 | R2: 5 | S2: 5 | T2: Gen Z (1997 - 2012)
B3: 5 | C3: 5 | D3: 1 | E3: 3 | F3: 1 | G3: 5 | H3: 5 | I3: 5 | J3: 5 | K3: 5 | L3: 5 | M3: 3 | N3: 3 | O3: 5 | P3: 5 | Q3: 5 | R3: 5 | S3: 5 | T3: Gen Z (1997 - 2012)
B4: 5 | C4: 5 | D4: 4 | E4: 4 | F4: 4 | G4: 5 | H4: 4 | I4: 4 | J4: 5 | K4: 5 | L4: 4 | M4: 4 | N4: 4 | O4: 2 | P4: 4 | Q4: 4 | R4: 4 | S4: 4 | T4: Gen Z (1997 - 2012)
B5: 3 | C5: 3 | D5: 3 | E5: 4 | F5: 3 | G5: 4 | H5: 4 | I5: 4 | J5: 4 | K5: 5 | L5: 4 | M5: 2 | N5: 3 | O5: 4 | P5: 3 | Q5: 4 | R5: 4 | S5: 2 | T5: Gen Z (1997 - 2012)
B6: 1 | C6: 1 | D6: 1 | E6: 1 | F6: 1 | G6: 1 | H6: 1 | I6: 1 | J6: 3 | K6: 1 | L6: 1 | M6: 1 | N6: 1 | O6: 1 | P6: 1 | Q6: 1 | R6: 1 | S6: 1 | T6: Gen Z (1997 - 2012)
B7: 4 | C7: 5 | D7: 4 | E7: 5 | F7: 4 | G7: 5 | H7: 4 | I7: 2 | J7: 2 | K7: 3 | L7: 2 | M7: 4 | N7: 3 | O7: 2 | P7: 3 | Q7: 3 | R7: 1 | S7: 3 | T7: Gen Z (1997 - 2012)
B8: 4 | C8: 4 | D8: 5 | E8: 1 | F8: 2 | G8: 4 | H8: 4 | I8: 1 | J8: 5 | K8: 4 | L8: 4 | M8: 2 | N8: 1 | O8: 5 | P8: 5 | Q8: 5 | R8: 5 | S8: 5 | T8: Gen Z (1997 - 2012)
B9: 4 | C9: 2 | D9: 5 | E9: 2 | F9: 5 | G9: 4 | H9: 1 | I9: 4 | J9: 5 | K9: 5 | L9: 4 | M9: 2 | N9: 2 | O9: 4 | P9: 5 | Q9: 5 | R9: 5 | S9: 5 | T9: Gen Z (1997 - 2012)
B10: 5 | C10: 5 | D10: 4 | E10: 5 | F10: 5 | G10: 4 | H10: 4 | I10: 4 | J10: 4 | K10: 4 | L10: 4 | M10: 4 | N10: 4 | O10: 4 | P10: 4 | Q10: 4 | R10: 5 | S10: 5 | T10: Gen X (1965 - 1980)
B11: 5 | C11: 5 | D11: 4 | E11: 4 | F11: 5 | G11: 5 | H11: 4 | I11: 2 | J11: 5 | K11: 5 | L11: 5 | M11: 5 | N11: 4 | O11: 5 | P11: 5 | Q11: 5 | R11: 5 | S11: 5 | T11: Gen Z (1997 - 2012)
B12: 5 | C12: 4 | D12: 3 | E12: 2 | F12: 2 | G12: 4 | H12: 2 | I12: 3 | J12: 5 | K12: 5 | L12: 4 | M12: 4 | N12: 2 | O12: 3 | P12: 5 | Q12: 5 | R12: 5 | S12: 5 | T12: Gen Z (1997 - 2012)
B13: 1 | C13: 3 | D13: 2 | E13: 3 | F13: 4 | G13: 4 | H13: 3 | I13: 4 | J13: 5 | K13: 2 | L13: 4 | M13: 3 | N13: 2 | O13: 2 | P13: 4 | Q13: 4 | R13: 4 | S13: 4 | T13: Gen Z (1997 - 2012)
... B39: 5 | C39: 4 | D39: 4 | E39: 3 | F39: 4 | G39: 4 | H39: 4 | I39: 3 | J39: 3 | K39: 2 | L39: 2 | M39: 2 | N39: 2 | O39: 3 | P39: 4 | Q39: 3 | R39: 5 | S39: 5 | T39: Gen Z (1997 - 2012)
A41: %ofagree (4-5) | B41: =COUNTIF(B2:B39, ">=4")/COUNT(B2:B39) -> 0.86842105 | C41: =COUNTIF(C2:C39, ">=4")/COUNT(C2:C39) -> 0.73684211 | D41: =COUNTIF(D2:D39, ">=4")/COUNT(D2:D39) -> 0.76315789 | E41: =COUNTIF(E2:E39, ">=4")/COUNT(E2:E39) -> 0.68421053 | F41: =COUNTIF(F2:F39, ">=4")/COUNT(F2:F39) -> 0.76315789 | G41: =COUNTIF(G2:G39, ">=4")/COUNT(G2:G39) -> 0.89473684 | H41: =COUNTIF(H2:H39, ">=4")/COUNT(H2:H39) -> 0.63157895 | I41: =COUNTIF(I2:I39, ">=4")/COUNT(I2:I39) -> 0.52631579 | ... S41: =COUNTIF(S2:S39, ">=4")/COUNT(S2:S39) -> 0.78947368

Sheet Descrptive Statistics
A3: Overall Descriptive statistics Summary
A4: Protecting the environment should be prioritized. | C4: I consider it my personal responsibility to reduce waste. | E4: Companies hold the responsibility to minimize the environmental impact of their products. | G4: I prefer to purchase products that are environmentally friendly, even if they come at a higher price. | I4: I prefer products with eco-friendly packaging over conventional packaging. | K4: I worry about how today’s packaging waste will affect future generations. | M4: I actively seek information regarding the sustainability of the products I purchase. | O4: I trust in a company's claims regarding the environmental benefits of its packaging | Q4: Brands often exaggerate the environmental benefits of their products. | S4: I often find it challenging to determine which brands truly practice sustainability | U4: I would be willing to change my purchasing habits based on new information about a product's environmental impact. | W4: Imagine your usual bread costs 400 forints. If that same bread cost 460 forints, would you be willing to pay an additional 10% for eco-friendly packaging?" | Y4: I would pick a more expensive product with eco-friendly packaging instead of a cheaper one with regular packaging. | AA4: I think companies should use sustainable packaging, even if their products cost more. | AC4: I am cautious about trusting sustainability claims made by brands | AE4: I worry that some companies pretend to be eco-friendly just to attract customers. | AG4: I think there should be stricter rules to stop companies from making false environmental claims. | AI4: I get frustrated when brands use “green” words without proving their products are truly sustainable.
A6: Mean | B6: 4.2105263 | C6: Mean | D6: 4.0263158 | E6: Mean | F6: 3.9210526 | G6: Mean | H6: 3.6315789 | I6: Mean | J6: 3.8947368 | K6: Mean | L6: 4.3157895 | M6: Mean | N6: 3.4473684 | O6: Mean | P6: 3.1578947 | Q6: Mean | R6: 4.0263158 | S6: Mean | T6: 3.5263158 | U6: Mean | V6: 3.3157895 | W6: Mean | X6: 3.5526316 | Y6: Mean | Z6: 3.1052632 | AA6: Mean | AB6: 3.3947368 | AC6: Mean | AD6: 3.5526316 | AE6: Mean | AF6: 3.8421053 | AG6: Mean | AH6: 4.4736842 | AI6: Mean | AJ6: 4.2368421
A7: Standard Error | B7: 0.18149801 | C7: Standard Error | D7: 0.18663312 | E7: Standard Error | F7: 0.17439829 | G7: Standard Error | H7: 0.17043603 | I7: Standard Error | J7: 0.18004849 | K7: Standard Error | L7: 0.14658397 | M7: Standard Error | N7: 0.17568143 | O7: Standard Error | P7: 0.21509969 | Q7: Standard Error | R7: 0.17482705 | S7: Standard Error | T7: 0.20566944 | U7: Standard Error | V7: 0.20693957 | W7: Standard Error | X7: 0.17158523 | Y7: Standard Error | Z7: 0.19153298 | AA7: Standard Error | AB7: 0.19429807 | AC7: Standard Error | AD7: 0.19849135 | AE7: Standard Error | AF7: 0.18293605 | AG7: Standard Error | AH7: 0.16755646 | AI7: Standard Error | AJ7: 0.18643244
A8: Median | B8: 4.5 | C8: Median | D8: 4 | E8: Median | F8: 4 | G8: Median | H8: 4 | I8: Median | J8: 4 | K8: Median | L8: 4.5 | M8: Median | N8: 4 | O8: Median | P8: 4 | Q8: Median | R8: 4 | S8: Median | T8: 4 | U8: Median | V8: 4 | W8: Median | X8: 4 | Y8: Median | Z8: 3 | AA8: Median | AB8: 4 | AC8: Median | AD8: 4 | AE8: Median | AF8: 4 | AG8: Median | AH8: 5 | AI8: Median | AJ8: 5
A9: Mode | B9: 5 | C9: Mode | D9: 5 | E9: Mode | F9: 4 | G9: Mode | H9: 4 | I9: Mode | J9: 4 | K9: Mode | L9: 5 | M9: Mode | N9: 4 | O9: Mode | P9: 4 | Q9: Mode | R9: 5 | S9: Mode | T9: 4 | U9: Mode | V9: 4 | W9: Mode | X9: 4 | Y9: Mode | Z9: 4 | AA9: Mode | AB9: 4 | AC9: Mode | AD9: 4 | AE9: Mode | AF9: 5 | AG9: Mode | AH9: 5 | AI9: Mode | AJ9: 5
A10: Standard Deviation | B10: 1.1188289 | C10: Standard Deviation | D10: 1.1504838 | E10: Standard Deviation | F10: 1.0750633 | G10: Standard Deviation | H10: 1.0506382 | I10: Standard Deviation | J10: 1.1098934 | K10: Standard Deviation | L10: 0.90360429 | M10: Standard Deviation | N10: 1.0829731 | O10: Standard Deviation | P10: 1.3259635 | Q10: Standard Deviation | R10: 1.0777063 | S10: Standard Deviation | T10: 1.2678316 | U10: Standard Deviation | V10: 1.2756612 | W10: Standard Deviation | X10: 1.0577224 | Y10: Standard Deviation | Z10: 1.1806886 | AA10: Standard Deviation | AB10: 1.1977338 | AC10: Standard Deviation | AD10: 1.2235829 | AE10: Standard Deviation | AF10: 1.1276936 | AG10: Standard Deviation | AH10: 1.0328874 | AI10: Standard Deviation | AJ10: 1.1492468
A11: Sample Variance | B11: 1.2517781 | C11: Sample Variance | D11: 1.3236131 | E11: Sample Variance | F11: 1.155761 | G11: Sample Variance | H11: 1.1038407 | I11: Sample Variance | J11: 1.2318634 | K11: Sample Variance | L11: 0.81650071 | M11: Sample Variance | N11: 1.1728307 | O11: Sample Variance | P11: 1.7581792 | Q11: Sample Variance | R11: 1.1614509 | S11: Sample Variance | T11: 1.6073969 | U11: Sample Variance | V11: 1.6273115 | W11: Sample Variance | X11: 1.1187767 | Y11: Sample Variance | Z11: 1.3940256 | AA11: Sample Variance | AB11: 1.4345661 | AC11: Sample Variance | AD11: 1.497155 | AE11: Sample Variance | AF11: 1.2716927 | AG11: Sample Variance | AH11: 1.0668563 | AI11: Sample Variance | AJ11: 1.3207681
A12: Kurtosis | B12: 3.4440706 | C12: Kurtosis | D12: 0.7942952 | E12: Kurtosis | F12: 1.3265553 | G12: Kurtosis | H12: 0.56583799 | I12: Kurtosis | J12: 0.92115812 | K12: Kurtosis | L12: 4.3671982 | M12: Kurtosis | N12: -0.30646116 | O12: Kurtosis | P12: -1.1225521 | Q12: Kurtosis | R12: -0.75614549 | S12: Kurtosis | T12: -1.3749331 | U12: Kurtosis | V12: -1.1505445 | W12: Kurtosis | X12: -0.44681119 | Y12: Kurtosis | Z12: -1.0473684 | AA12: Kurtosis | AB12: -0.96818312 | AC12: Kurtosis | AD12: -0.46367171 | AE12: Kurtosis | AF12: -0.48784575 | AG12: Kurtosis | AH12: 5.987721 | AI12: Kurtosis | AJ12: 0.83618616
A13: Skewness | B13: -1.9067557 | C13: Skewness | D13: -1.1777708 | E13: Skewness | F13: -1.2135243 | G13: Skewness | H13: -0.95834401 | I13: Skewness | J13: -1.1593537 | K13: Skewness | L13: -1.8489639 | M13: Skewness | N13: -0.73318218 | O13: Skewness | P13: -0.37891479 | Q13: Skewness | R13: -0.73830186 | S13: Skewness | T13: -0.27222287 | U13: Skewness | V13: -0.30561417 | W13: Skewness | X13: -0.57959784 | Y13: Skewness | Z13: -0.10975954 | AA13: Skewness | AB13: -0.33528863 | AC13: Skewness | AD13: -0.64242884 | AE13: Skewness | AF13: -0.62787775 | AG13: Skewness | AH13: -2.488816 | AI13: Skewness | AJ13: -1.3950901
A14: Range | B14: 4 | C14: Range | D14: 4 | E14: Range | F14: 4 | G14: Range | H14: 4 | I14: Range | J14: 4 | K14: Range | L14: 4 | M14: Range | N14: 4 | O14: Range | P14: 4 | Q14: Range | R14: 3 | S14: Range | T14: 4 | U14: Range | V14: 4 | W14: Range | X14: 4 | Y14: Range | Z14: 4 | AA14: Range | AB14: 4 | AC14: Range | AD14: 4 | AE14: Range | AF14: 4 | AG14: Range | AH14: 4 | AI14: Range | AJ14: 4
A15: Minimum | B15: 1 | C15: Minimum | D15: 1 | E15: Minimum | F15: 1 | G15: Minimum | H15: 1 | I15: Minimum | J15: 1 | K15: Minimum | L15: 1 | M15: Minimum | N15: 1 | O15: Minimum | P15: 1 | Q15: Minimum | R15: 2 | S15: Minimum | T15: 1 | U15: Minimum | V15: 1 | W15: Minimum | X15: 1 | Y15: Minimum | Z15: 1 | AA15: Minimum | AB15: 1 | AC15: Minimum | AD15: 1 | AE15: Minimum | AF15: 1 | AG15: Minimum | AH15: 1 | AI15: Minimum | AJ15: 1
A16: Maximum | B16: 5 | C16: Maximum | D16: 5 | E16: Maximum | F16: 5 | G16: Maximum | H16: 5 | I16: Maximum | J16: 5 | K16: Maximum | L16: 5 | M16: Maximum | N16: 5 | O16: Maximum | P16: 5 | Q16: Maximum | R16: 5 | S16: Maximum | T16: 5 | U16: Maximum | V16: 5 | W16: Maximum | X16: 5 | Y16: Maximum | Z16: 5 | AA16: Maximum | AB16: 5 | AC16: Maximum | AD16: 5 | AE16: Maximum | AF16: 5 | AG16: Maximum | AH16: 5 | AI16: Maximum | AJ16: 5
A17: Sum | B17: 160 | C17: Sum | D17: 153 | E17: Sum | F17: 149 | G17: Sum | H17: 138 | I17: Sum | J17: 148 | K17: Sum | L17: 164 | M17: Sum | N17: 131 | O17: Sum | P17: 120 | Q17: Sum | R17: 153 | S17: Sum | T17: 134 | U17: Sum | V17: 126 | W17: Sum | X17: 135 | Y17: Sum | Z17: 118 | AA17: Sum | AB17: 129 | AC17: Sum | AD17: 135 | AE17: Sum | AF17: 146 | AG17: Sum | AH17: 170 | AI17: Sum | AJ17: 161
A18: Count | B18: 38 | C18: Count | D18: 38 | E18: Count | F18: 38 | G18: Count | H18: 38 | I18: Count | J18: 38 | K18: Count | L18: 38 | M18: Count | N18: 38 | O18: Count | P18: 38 | Q18: Count | R18: 38 | S18: Count | T18: 38 | U18: Count | V18: 38 | W18: Count | X18: 38 | Y18: Count | Z18: 38 | AA18: Count | AB18: 38 | AC18: Count | AD18: 38 | AE18: Count | AF18: 38 | AG18: Count | AH18: 38 | AI18: Count | AJ18: 38
A21: Gen-X Descriptive statistics Summary
A22: Protecting the environment should be prioritized. | C22: I consider it my personal responsibility to reduce waste. | E22: Companies hold the responsibility to minimize the environmental impact of their products. | G22: I prefer to purchase products that are environmentally friendly, even if they come at a higher price. | I22: I prefer products with eco-friendly packaging over conventional packaging. | K22: I worry about how today’s packaging waste will affect future generations. | M22: I actively seek information regarding the sustainability of the products I purchase. | O22: I trust in a company's claims regarding the environmental benefits of its packaging | Q22: Brands often exaggerate the environmental benefits of their products. | S22: I often find it challenging to determine which brands truly practice sustainability | U22: I would be willing to change my purchasing habits based on new information about a product's environmental impact. | W22: Imagine your usual bread costs 400 forints. If that same bread cost 460 forints, would you be willing to pay an additional 10% for eco-friendly packaging?" | Y22: I would pick a more expensive product with eco-friendly packaging instead of a cheaper one with regular packaging. | AA22: I think companies should use sustainable packaging, even if their products cost more. | AC22: I am cautious about trusting sustainability claims made by brands | AE22: I worry that some companies pretend to be eco-friendly just to attract customers. | AG22: I think there should be stricter rules to stop companies from making false environmental claims. | AI22: I get frustrated when brands use “green” words without proving their products are truly sustainable.
A24: Mean | B24: 4.6363636 | C24: Mean | D24: 4.5454545 | E24: Mean | F24: 4.3636364 | G24: Mean | H24: 4.1818182 | I24: Mean | J24: 4.3636364 | K24: Mean | L24: 4.4545455 | M24: Mean | N24: 3.1818182 | O24: Mean | P24: 2.5454545 | Q24: Mean | R24: 4.3636364 | S24: Mean | T24: 4 | U24: Mean | V24: 3.0909091 | W24: Mean | X24: 3.6363636 | Y24: Mean | Z24: 3.5454545 | AA24: Mean | AB24: 3.6363636 | AC24: Mean | AD24: 2.9090909 | AE24: Mean | AF24: 4.3636364 | AG24: Mean | AH24: 4.7272727 | AI24: Mean | AJ24: 4.3636364
A25: Standard Error | B25: 0.15212 | C25: Standard Error | D25: 0.24729946 | E25: Standard Error | F25: 0.24393469 | G25: Standard Error | H25: 0.26347958 | I25: Standard Error | J25: 0.24393469 | K25: Standard Error | L25: 0.20730462 | M25: Standard Error | N25: 0.26347958 | O25: Standard Error | P25: 0.45454545 | Q25: Standard Error | R25: 0.24393469 | S25: Standard Error | T25: 0.33028913 | U25: Standard Error | V25: 0.43598468 | W25: Standard Error | X25: 0.27872199 | Y25: Standard Error | Z25: 0.34015067 | AA25: Standard Error | AB25: 0.30962521 | AC25: Standard Error | AD25: 0.43598468 | AE25: Standard Error | AF25: 0.24393469 | AG25: Standard Error | AH25: 0.14083576 | AI25: Standard Error | AJ25: 0.30962521
A26: Median | B26: 5 | C26: Median | D26: 5 | E26: Median | F26: 5 | G26: Median | H26: 4 | I26: Median | J26: 5 | K26: Median | L26: 5 | M26: Median | N26: 3 | O26: Median | P26: 2 | Q26: Median | R26: 5 | S26: Median | T26: 4 | U26: Median | V26: 3 | W26: Median | X26: 4 | Y26: Median | Z26: 4 | AA26: Median | AB26: 4 | AC26: Median | AD26: 3 | AE26: Median | AF26: 5 | AG26: Median | AH26: 5 | AI26: Median | AJ26: 5
A27: Mode | B27: 5 | C27: Mode | D27: 5 | E27: Mode | F27: 5 | G27: Mode | H27: 4 | I27: Mode | J27: 5 | K27: Mode | L27: 5 | M27: Mode | N27: 4 | O27: Mode | P27: 1 | Q27: Mode | R27: 5 | S27: Mode | T27: 4 | U27: Mode | V27: 4 | W27: Mode | X27: 4 | Y27: Mode | Z27: 4 | AA27: Mode | AB27: 4 | AC27: Mode | AD27: 2 | AE27: Mode | AF27: 5 | AG27: Mode | AH27: 5 | AI27: Mode | AJ27: 5
A28: Standard Deviation | B28: 0.50452498 | C28: Standard Deviation | D28: 0.82019953 | E28: Standard Deviation | F28: 0.80903983 | G28: Standard Deviation | H28: 0.8738629 | I28: Standard Deviation | J28: 0.80903983 | K28: Standard Deviation | L28: 0.68755165 | M28: Standard Deviation | N28: 0.8738629 | O28: Standard Deviation | P28: 1.5075567 | Q28: Standard Deviation | R28: 0.80903983 | S28: Standard Deviation | T28: 1.0954451 | U28: Standard Deviation | V28: 1.4459976 | W28: Standard Deviation | X28: 0.92441628 | Y28: Standard Deviation | Z28: 1.1281521 | AA28: Standard Deviation | AB28: 1.0269106 | AC28: Standard Deviation | AD28: 1.4459976 | AE28: Standard Deviation | AF28: 0.80903983 | AG28: Standard Deviation | AH28: 0.46709937 | AI28: Standard Deviation | AJ28: 1.0269106
A29: Sample Variance | B29: 0.25454545 | C29: Sample Variance | D29: 0.67272727 | E29: Sample Variance | F29: 0.65454545 | G29: Sample Variance | H29: 0.76363636 | I29: Sample Variance | J29: 0.65454545 | K29: Sample Variance | L29: 0.47272727 | M29: Sample Variance | N29: 0.76363636 | O29: Sample Variance | P29: 2.2727273 | Q29: Sample Variance | R29: 0.65454545 | S29: Sample Variance | T29: 1.2 | U29: Sample Variance | V29: 2.0909091 | W29: Sample Variance | X29: 0.85454545 | Y29: Sample Variance | Z29: 1.2727273 | AA29: Sample Variance | AB29: 1.0545455 | AC29: Sample Variance | AD29: 2.0909091 | AE29: Sample Variance | AF29: 0.65454545 | AG29: Sample Variance | AH29: 0.21818182 | AI29: Sample Variance | AJ29: 1.0545455
A30: Kurtosis | B30: -1.9642857 | C30: Kurtosis | D30: 0.6294132 | E30: Kurtosis | F30: -0.76388889 | G30: Kurtosis | H30: 3.5232426 | I30: Kurtosis | J30: -0.76388889 | K30: Kurtosis | L30: 0.081360947 | M30: Kurtosis | N30: -1.6213152 | O30: Kurtosis | P30: -1.584 | Q30: Kurtosis | R30: -0.76388889 | S30: Kurtosis | T30: 0.41666667 | U30: Kurtosis | V30: -1.2448645 | W30: Kurtosis | X30: -0.44816659 | Y30: Kurtosis | Z30: -1.1823129 | AA30: Kurtosis | AB30: -0.59403488 | AC30: Kurtosis | AD30: -1.2448645 | AE30: Kurtosis | AF30: -0.76388889 | AG30: Kurtosis | AH30: -0.76388889 | AI30: Kurtosis | AJ30: 1.7439556
A31: Skewness | B31: -0.66068747 | C31: Skewness | D31: -1.5047975 | E31: Skewness | F31: -0.84691156 | G31: Skewness | H31: -1.5076282 | I31: Skewness | J31: -0.84691156 | K31: Skewness | L31: -0.93233089 | M31: Skewness | N31: -0.40869438 | O31: Skewness | P31: 0.32193371 | Q31: Skewness | R31: -0.84691156 | S31: Skewness | T31: -1.1157311 | U31: Skewness | V31: -0.19043069 | W31: Skewness | X31: -0.02301625 | Y31: Skewness | Z31: -0.3925509 | AA31: Skewness | AB31: -0.44772164 | AC31: Skewness | AD31: 0.19043069 | AE31: Skewness | AF31: -0.84691156 | AG31: Skewness | AH31: -1.1893734 | AI31: Skewness | AJ31: -1.5838153
A32: Range | B32: 1 | C32: Range | D32: 2 | E32: Range | F32: 2 | G32: Range | H32: 3 | I32: Range | J32: 2 | K32: Range | L32: 2 | M32: Range | N32: 2 | O32: Range | P32: 4 | Q32: Range | R32: 2 | S32: Range | T32: 3 | U32: Range | V32: 4 | W32: Range | X32: 3 | Y32: Range | Z32: 3 | AA32: Range | AB32: 3 | AC32: Range | AD32: 4 | AE32: Range | AF32: 2 | AG32: Range | AH32: 1 | AI32: Range | AJ32: 3
A33: Minimum | B33: 4 | C33: Minimum | D33: 3 | E33: Minimum | F33: 3 | G33: Minimum | H33: 2 | I33: Minimum | J33: 3 | K33: Minimum | L33: 3 | M33: Minimum | N33: 2 | O33: Minimum | P33: 1 | Q33: Minimum | R33: 3 | S33: Minimum | T33: 2 | U33: Minimum | V33: 1 | W33: Minimum | X33: 2 | Y33: Minimum | Z33: 2 | AA33: Minimum | AB33: 2 | AC33: Minimum | AD33: 1 | AE33: Minimum | AF33: 3 | AG33: Minimum | AH33: 4 | AI33: Minimum | AJ33: 2
A34: Maximum | B34: 5 | C34: Maximum | D34: 5 | E34: Maximum | F34: 5 | G34: Maximum | H34: 5 | I34: Maximum | J34: 5 | K34: Maximum | L34: 5 | M34: Maximum | N34: 4 | O34: Maximum | P34: 5 | Q34: Maximum | R34: 5 | S34: Maximum | T34: 5 | U34: Maximum | V34: 5 | W34: Maximum | X34: 5 | Y34: Maximum | Z34: 5 | AA34: Maximum | AB34: 5 | AC34: Maximum | AD34: 5 | AE34: Maximum | AF34: 5 | AG34: Maximum | AH34: 5 | AI34: Maximum | AJ34: 5
A35: Sum | B35: 51 | C35: Sum | D35: 50 | E35: Sum | F35: 48 | G35: Sum | H35: 46 | I35: Sum | J35: 48 | K35: Sum | L35: 49 | M35: Sum | N35: 35 | O35: Sum | P35: 28 | Q35: Sum | R35: 48 | S35: Sum | T35: 44 | U35: Sum | V35: 34 | W35: Sum | X35: 40 | Y35: Sum | Z35: 39 | AA35: Sum | AB35: 40 | AC35: Sum | AD35: 32 | AE35: Sum | AF35: 48 | AG35: Sum | AH35: 52 | AI35: Sum | AJ35: 48
A36: Count | B36: 11 | C36: Count | D36: 11 | E36: Count | F36: 11 | G36: Count | H36: 11 | I36: Count | J36: 11 | K36: Count | L36: 11 | M36: Count | N36: 11 | O36: Count | P36: 11 | Q36: Count | R36: 11 | S36: Count | T36: 11 | U36: Count | V36: 11 | W36: Count | X36: 11 | Y36: Count | Z36: 11 | AA36: Count | AB36: 11 | AC36: Count | AD36: 11 | AE36: Count | AF36: 11 | AG36: Count | AH36: 11 | AI36: Count | AJ36: 11
A39: Gen-Z Descriptive statistics Summary
A40: Protecting the environment should be prioritized. | C40: I consider it my personal responsibility to reduce waste. | E40: Companies hold the responsibility to minimize the environmental impact of their products. | G40: I prefer to purchase products that are environmentally friendly, even if they come at a higher price. | I40: I prefer products with eco-friendly packaging over conventional packaging. | K40: I worry about how today’s packaging waste will affect future generations. | M40: I actively seek information regarding the sustainability of the products I purchase. | O40: I trust in a company's claims regarding the environmental benefits of its packaging | Q40: Brands often exaggerate the environmental benefits of their products. | S40: I often find it challenging to determine which brands truly practice sustainability | U40: I would be willing to change my purchasing habits based on new information about a product's environmental impact. | W40: Imagine your usual bread costs 400 forints. If that same bread cost 460 forints, would you be willing to pay an additional 10% for eco-friendly packaging?" | Y40: I would pick a more expensive product with eco-friendly packaging instead of a cheaper one with regular packaging. | AA40: I think companies should use sustainable packaging, even if their products cost more. | AC40: I am cautious about trusting sustainability claims made by brands | AE40: I worry that some companies pretend to be eco-friendly just to attract customers. | AG40: I think there should be stricter rules to stop companies from making false environmental claims. | AI40: I get frustrated when brands use “green” words without proving their products are truly sustainable.
A42: Mean | B42: 4.037037 | C42: Mean | D42: 3.8148148 | E42: Mean | F42: 3.7407407 | G42: Mean | H42: 3.4074074 | I42: Mean | J42: 3.7037037 | K42: Mean | L42: 4.2592593 | M42: Mean | N42: 3.5555556 | O42: Mean | P42: 3.4074074 | Q42: Mean | R42: 3.8888889 | S42: Mean | T42: 3.3333333 | U42: Mean | V42: 3.4074074 | W42: Mean | X42: 3.5185185 | Y42: Mean | Z42: 2.9259259 | AA42: Mean | AB42: 3.2962963 | AC42: Mean | AD42: 3.8148148 | AE42: Mean | AF42: 3.6296296 | AG42: Mean | AH42: 4.3703704 | AI42: Mean | AJ42: 4.1851852
A43: Standard Error | B43: 0.24156117 | C43: Standard Error | D43: 0.23288747 | E43: Standard Error | F43: 0.21742204 | G43: Standard Error | H43: 0.20155563 | I43: Standard Error | J43: 0.2252875 | K43: Standard Error | L43: 0.18941049 | M43: Standard Error | N43: 0.22222222 | O43: Standard Error | P43: 0.22808043 | Q43: Standard Error | R43: 0.22222222 | S43: Standard Error | T43: 0.25035587 | U43: Standard Error | V43: 0.23424279 | W43: Standard Error | X43: 0.21596118 | Y43: Standard Error | Z43: 0.22598897 | AA43: Standard Error | AB43: 0.24351892 | AC43: Standard Error | AD43: 0.1999789 | AE43: Standard Error | AF43: 0.22738541 | AG43: Standard Error | AH43: 0.22738541 | AI43: Standard Error | AJ43: 0.23288747
A44: Median | B44: 4 | C44: Median | D44: 4 | E44: Median | F44: 4 | G44: Median | H44: 4 | I44: Median | J44: 4 | K44: Median | L44: 4 | M44: Median | N44: 4 | O44: Median | P44: 4 | Q44: Median | R44: 4 | S44: Median | T44: 3 | U44: Median | V44: 4 | W44: Median | X44: 4 | Y44: Median | Z44: 3 | AA44: Median | AB44: 4 | AC44: Median | AD44: 4 | AE44: Median | AF44: 4 | AG44: Median | AH44: 5 | AI44: Median | AJ44: 5
A45: Mode | B45: 5 | C45: Mode | D45: 4 | E45: Mode | F45: 4 | G45: Mode | H45: 4 | I45: Mode | J45: 4 | K45: Mode | L45: 5 | M45: Mode | N45: 4 | O45: Mode | P45: 4 | Q45: Mode | R45: 5 | S45: Mode | T45: 2 | U45: Mode | V45: 4 | W45: Mode | X45: 4 | Y45: Mode | Z45: 4 | AA45: Mode | AB45: 4 | AC45: Mode | AD45: 4 | AE45: Mode | AF45: 5 | AG45: Mode | AH45: 5 | AI45: Mode | AJ45: 5
A46: Standard Deviation | B46: 1.2551887 | C46: Standard Deviation | D46: 1.2101188 | E46: Standard Deviation | F46: 1.1297581 | G46: Standard Deviation | H46: 1.0473138 | I46: Standard Deviation | J46: 1.1706282 | K46: Standard Deviation | L46: 0.98420576 | M46: Standard Deviation | N46: 1.1547005 | O46: Standard Deviation | P46: 1.1851407 | Q46: Standard Deviation | R46: 1.1547005 | S46: Standard Deviation | T46: 1.3008873 | U46: Standard Deviation | V46: 1.2171612 | W46: Standard Deviation | X46: 1.1221672 | Y46: Standard Deviation | Z46: 1.1742731 | AA46: Standard Deviation | AB46: 1.2653615 | AC46: Standard Deviation | AD46: 1.0391208 | AE46: Standard Deviation | AF46: 1.1815293 | AG46: Standard Deviation | AH46: 1.1815293 | AI46: Standard Deviation | AJ46: 1.2101188
A47: Sample Variance | B47: 1.5754986 | C47: Sample Variance | D47: 1.4643875 | E47: Sample Variance | F47: 1.2763533 | G47: Sample Variance | H47: 1.0968661 | I47: Sample Variance | J47: 1.3703704 | K47: Sample Variance | L47: 0.96866097 | M47: Sample Variance | N47: 1.3333333 | O47: Sample Variance | P47: 1.4045584 | Q47: Sample Variance | R47: 1.3333333 | S47: Sample Variance | T47: 1.6923077 | U47: Sample Variance | V47: 1.4814815 | W47: Sample Variance | X47: 1.2592593 | Y47: Sample Variance | Z47: 1.3789174 | AA47: Sample Variance | AB47: 1.6011396 | AC47: Sample Variance | AD47: 1.0797721 | AE47: Sample Variance | AF47: 1.3960114 | AG47: Sample Variance | AH47: 1.3960114 | AI47: Sample Variance | AJ47: 1.4643875
A48: Kurtosis | B48: 1.849525 | C48: Kurtosis | D48: 0.38905525 | E48: Kurtosis | F48: 1.0008984 | G48: Kurtosis | H48: 0.3945124 | I48: Kurtosis | J48: 0.48286565 | K48: Kurtosis | L48: 4.1283187 | M48: Kurtosis | N48: 0.079615385 | O48: Kurtosis | P48: -0.57667927 | Q48: Kurtosis | R48: -1.1198077 | S48: Kurtosis | T48: -1.4622314 | U48: Kurtosis | V48: -1.2038885 | W48: Kurtosis | X48: -0.55918818 | Y48: Kurtosis | Z48: -0.96350591 | AA48: Kurtosis | AB48: -1.1165535 | AC48: Kurtosis | AD48: 0.79739294 | AE48: Kurtosis | AF48: -0.75725948 | AG48: Kurtosis | AH48: 3.8955883 | AI48: Kurtosis | AJ48: 0.74059198
A49: Skewness | B49: -1.5869894 | C49: Skewness | D49: -1.0237925 | E49: Skewness | F49: -1.1729755 | G49: Skewness | H49: -0.92863426 | I49: Skewness | J49: -1.0778725 | K49: Skewness | L49: -1.8761022 | M49: Skewness | N49: -0.95529264 | O49: Skewness | P49: -0.58540992 | Q49: Skewness | R49: -0.57757233 | S49: Skewness | T49: -4.24276e-16 | U49: Skewness | V49: -0.3202913 | W49: Skewness | X49: -0.66709959 | Y49: Skewness | Z49: -0.00056303513 | AA49: Skewness | AB49: -0.24001132 | AC49: Skewness | AD49: -0.93411624 | AE49: Skewness | AF49: -0.41046769 | AG49: Skewness | AH49: -2.1582545 | AI49: Skewness | AJ49: -1.3671359
...

Sheet t-Tests
B2: t-Test: Two-Sample Assuming Unequal Variances
B4: Question 1:
B5: Protecting the environment should be prioritized.
C6: Gen X | D6: Gen Z
B7: Mean | C7: 4.6363636 | D7: 4.037037
B8: Variance | C8: 0.25454545 | D8: 1.5754986
B9: Observations | C9: 11 | D9: 27
B10: Hypothesized Mean Difference | C10: 0
B11: df | C11: 36
B12: t Stat | C12: 2.0994488
B13: P(T<=t) one-tail | C13: 0.021425768
B14: t Critical one-tail | C14: 1.6882977
B15: P(T<=t) two-tail | C15: 0.042851536
B16: t Critical two-tail | C16: 2.028094
B18: Question 2:
C19: I consider it my personal responsibility to reduce waste.
C20: Gen X | D20: Gen Z
B21: Mean | C21: 4.5454545 | D21: 3.8148148
B22: Variance | C22: 0.67272727 | D22: 1.4643875
B23: Observations | C23: 11 | D23: 27
B24: Hypothesized Mean Difference | C24: 0
B25: df | C25: 27
B26: t Stat | C26: 2.1508614
B27: P(T<=t) one-tail | C27: 0.020298722
B28: t Critical one-tail | C28: 1.7032884
B29: P(T<=t) two-tail | C29: 0.040597444
B30: t Critical two-tail | C30: 2.0518305
B32: Question 3:
B33: Companies hold the responsibility to minimize the environmental impact of their products.
C34: Gen X | D34: Gen Z
B35: Mean | C35: 4.3636364 | D35: 3.7407407
B36: Variance | C36: 0.65454545 | D36: 1.2763533
B37: Observations | C37: 11 | D37: 27
B38: Hypothesized Mean Difference | C38: 0
B39: df | C39: 26
B40: t Stat | C40: 1.9062396
B41: P(T<=t) one-tail | C41: 0.033864978
B42: t Critical one-tail | C42: 1.7056179
B43: P(T<=t) two-tail | C43: 0.067729956
B44: t Critical two-tail | C44: 2.0555294
...

Sheet Summary
B2: Environmental Values & Responsibility
B3: Question | C3: Gen X Mean | D3: Gen Z Mean | E3: p-value | F3: Significant (p<0.05)? | G3: Mean Diff | H3: % Agree (4–5) | I3: Interpretation
B4: Protecting the environment should be prioritized | C4: 4.64 | D4: 4.04 | E4: 0.04 | F4: YES | G4: =C4-D4 -> 0.6 | H4: ='X&Z_Agrees_Avg'!B41 -> 0.86842105 | I4: since the p-value is 0.04, Gen X places significantly higher importance on environmental protection than Gen Z.
B5: Personal responsibility to reduce waste | C5: 4.55 | D5: 3.81 | E5: 0.04 | F5: YES | G5: 0.74 | H5: ='X&Z_Agrees_Avg'!C41 -> 0.73684211 | I5: since the p-value is 0.04, Gen X feels significantly stronger personal responsibility than Gen Z.
B6: Companies responsible for minimising environmental impact | C6: 4.36 | D6: 3.74 | E6: 0.07 | F6: NO | G6: 0.62 | H6: ='X&Z_Agrees_Avg'!D41 -> 0.76315789 | I6: since the p-value is less that 0.05, Both generations strongly agree; no significant difference.
B8: Sustainable Packaging Preferences & Price Sensitivity
B9: Question | C9: Gen X Mean | D9: Gen Z Mean | E9: p-value | F9: Significant? | G9: Mean Diff | H9: % Agree (4–5) | I9: Interpretation
B10: Prefer eco-friendly products even if higher price | C10: 4.18 | D10: 3.41 | E10: 0.03 | F10: YES | G10: =C10-D10 -> 0.77 | H10: ='X&Z_Agrees_Avg'!E41 -> 0.68421053 | I10: Gen X is significantly more willing to pay more for eco-friendly products.
B11: Prefer eco-friendly packaging over conventional | C11: 4.36 | D11: 3.7 | E11: 0.06 | F11: NO | G11: =C11-D11 -> 0.66 | H11: ='X&Z_Agrees_Avg'!F41 -> 0.76315789 | I11: Both generations prefer eco-packaging; difference not significant.
B12: Actively seek sustainability information | C12: 4.45 | D12: 4.26 | E12: 0.49 | F12: NO | G12: =C12-D12 -> 0.19 | H12: ='X&Z_Agrees_Avg'!H41 -> 0.63157895 | I12: Both groups show similarly high engagement in sustainability info-seeking.
B13: Willing to change purchasing habits for environmental impact | C13: 3.09 | D13: 3.41 | E13: 0.53 | F13: NO | G13: =C13-D13 -> -0.32 | H13: ='X&Z_Agrees_Avg'!L41 -> 0.55263158 | I13: No generational difference; moderate willingness to change behavior.
B14: Scenario: willing to pay +10% for eco packaging | C14: 3.64 | D14: 3.52 | E14: 0.74 | F14: NO | G14: =C14-D14 -> 0.12 | H14: ='X&Z_Agrees_Avg'!M41 -> 0.63157895 | I14: Majority are willing to pay +10%, but difference between generations is not significant.
B16: Trust, Greenwashing & Scepticism
B17: Question | C17: Gen X Mean | D17: Gen Z Mean | E17: p-value | F17: Significant? | G17: Mean Diff | H17: % Agree (4–5) | I17: Interpretation
B18: Trust company environmental claims | C18: 2.55 | D18: 3.41 | E18: 0.11 | F18: NO | G18: =C18-D18 -> -0.86 | H18: ='X&Z_Agrees_Avg'!I41 -> 0.52631579 | I18: Trust levels vary but not significantly; overall trust is moderate/low.
B19: Brands exaggerate environmental benefits | C19: 4.36 | D19: 3.89 | E19: 0.16 | F19: NO | G19: =C19-D19 -> 0.47 | H19: ='X&Z_Agrees_Avg'!J41 -> 0.71052632 | I19: High greenwashing concern in both groups.
B20: Hard to identify true sustainability | C20: 4 | D20: 3.33 | E20: 0.12 | F20: NO | G20: =C20-D20 -> 0.67 | H20: ='X&Z_Agrees_Avg'!K41 -> 0.57894737 | I20: Both groups struggle to determine which brands are actually sustainable.
B21: Cautious about trusting sustainability claims | C21: 2.91 | D21: 3.81 | E21: 0.08 | F21: NO | G21: =C21-D21 -> -0.9 | H21: ='X&Z_Agrees_Avg'!P41 -> 0.60526316 | I21: Both groups cautious; Gen Z slightly more skeptical but not significantly.
B22: Companies pretend to be eco-friendly for marketing | C22: 4.36 | D22: 3.63 | E22: 0.04 | F22: YES | G22: =C22-D22 -> 0.73 | H22: ='X&Z_Agrees_Avg'!Q41 -> 0.63157895 | I22: Gen X is significantly more concerned about fake eco-friendliness.
B23: Frustrated by vague “green” terms | C23: 4.36 | D23: 4.19 | E23: 0.65 | F23: NO | G23: =C23-D23 -> 0.17 | H23: ='X&Z_Agrees_Avg'!S41 -> 0.78947368 | I23: High frustration across both generations.
B26: Regulation & Policy
B27: Question | C27: Gen X Mean | D27: Gen Z Mean | E27: p-value | F27: Significant? | G27: Mean Diff | H27: % Agree (4–5) | I27: Interpretation
B28: Stricter rules needed to stop false claims | C28: 4.73 | D28: 4.37 | E28: 0.19 | F28: NO | G28: =C28-D28 -> 0.36 | H28: ='X&Z_Agrees_Avg'!R41 -> 0.92105263 | I28: Strong support for regulation across both groups.

Sheet Charts
